 * Serving Flask app "init" (lazy loading)
 * Environment: production
   WARNING: Do not use the development server in a production environment.
   Use a production WSGI server instead.
 * Debug mode: off
 * Running on http://0.0.0.0:5009/ (Press CTRL+C to quit)
127.0.0.1 - - [01/Mar/2019 13:29:11] "GET / HTTP/1.1" 200 -
127.0.0.1 - - [01/Mar/2019 13:29:12] "GET / HTTP/1.1" 200 -
127.0.0.1 - - [01/Mar/2019 13:29:15] "GET /null HTTP/1.1" 404 -
Error summary: {'faultMessage': '[SelectorError.INVALID_PREDICATE_VALUE @ serviceSelector]', 'requestId': '00058307915af8470a374c91d608f028', 'serviceName': 'AdGroupService', 'methodName': 'get', 'operations': '1', 'responseTime': '78'}
127.0.0.1 - - [01/Mar/2019 13:30:10] "GET /uploads/image.png HTTP/1.1" 200 -
127.0.0.1 - - [01/Mar/2019 13:30:50] "POST /upload HTTP/1.1" 200 -
127.0.0.1 - - [01/Mar/2019 13:31:10] "GET / HTTP/1.1" 200 -
127.0.0.1 - - [01/Mar/2019 13:31:14] "GET /null HTTP/1.1" 404 -
 * Serving Flask app "init" (lazy loading)
 * Environment: production
   WARNING: Do not use the development server in a production environment.
   Use a production WSGI server instead.
 * Debug mode: off
Traceback (most recent call last):
  File "init.py", line 107, in <module>
    app.run(host='0.0.0.0', port=5009)
  File "/home/ibrahima/.local/lib/python3.6/site-packages/flask/app.py", line 943, in run
    run_simple(host, port, self, **options)
  File "/home/ibrahima/.local/lib/python3.6/site-packages/werkzeug/serving.py", line 814, in run_simple
    inner()
  File "/home/ibrahima/.local/lib/python3.6/site-packages/werkzeug/serving.py", line 774, in inner
    fd=fd)
  File "/home/ibrahima/.local/lib/python3.6/site-packages/werkzeug/serving.py", line 660, in make_server
    passthrough_errors, ssl_context, fd=fd)
  File "/home/ibrahima/.local/lib/python3.6/site-packages/werkzeug/serving.py", line 577, in __init__
    self.address_family), handler)
  File "/usr/lib/python3.6/socketserver.py", line 453, in __init__
    self.server_bind()
  File "/usr/lib/python3.6/http/server.py", line 136, in server_bind
    socketserver.TCPServer.server_bind(self)
  File "/usr/lib/python3.6/socketserver.py", line 467, in server_bind
    self.socket.bind(self.server_address)
OSError: [Errno 98] Address already in use
